Workbook

Sheet 01_ACCUEIL
A1: SADesk | TABLEAU DE SUIVI DE TRÉSORERIE
A3: Pilotez votre trésorerie simplement.
A5: 1. Configurez vos paramètres • 2. Saisissez vos flux • 3. Consultez vos prévisions et alertes
A7: 💰 SAISIR MES FLUX | C7: 📊 VOIR MA TRÉSORERIE | E7: ⚠ VOIR MES ALERTES
A12: Les montants d'exemple sont fictifs. Les cellules bleues sont à renseigner ; les cellules blanches sont calculées automatiquement.
A16: Dernière mise à jour : 19/09/2026 · Outil de gestion, non comptable.

Sheet 02_PARAMETRES
A1: PARAMÈTRES DE L'ENTREPRISE | B1: Valeur
A2: Nom de l'entreprise | B2: Entreprise exemple
A3: Période de suivi | B3: 90 jours
A4: Devise | B4: EUR
A6: TRÉSORERIE | B6: Valeur
A7: Solde initial | B7: 25000
A8: Seuil de sécurité | B8: 10000
A9: Date du solde initial | B9: 46265.917

Sheet 03_FLUX
A1: Saisissez un montant toujours positif : le type de flux détermine automatiquement son impact sur la trésorerie.
A2: Date | B2: Type | C2: Catégorie | D2: Libellé | E2: Montant | F2: Statut | G2: Commentaire | H2: Impact trésorerie
A3: 46269.917 | B3: Encaissement | C3: Ventes | D3: Facture ABC | E3: 3500 | F3: Prévu | G3: Exemple fictif | H3: =IF(B3="Encaissement",E3,-E3)
A4: 46271.917 | B4: Décaissement | C4: Fournisseurs | D4: Matériaux | E4: 1200 | F4: Prévu | G4: Exemple fictif | H4: =IF(B4="Encaissement",E4,-E4)
A5: 46274.917 | B5: Décaissement | C5: Salaires | D5: Salaires | E5: 5000 | F5: Prévu | G5: Exemple fictif | H5: =IF(B5="Encaissement",E5,-E5)
A6: 46279.917 | B6: Encaissement | C6: Ventes | D6: Facture XYZ | E6: 2800 | F6: Réalisé | G6: Exemple fictif | H6: =IF(B6="Encaissement",E6,-E6)
H7: =IF(B7="","",IF(B7="Encaissement",E7,-E7))
H8: =IF(B8="","",IF(B8="Encaissement",E8,-E8))
H9: =IF(B9="","",IF(B9="Encaissement",E9,-E9))
H10: =IF(B10="","",IF(B10="Encaissement",E10,-E10))
H11: =IF(B11="","",IF(B11="Encaissement",E11,-E11))
H12: =IF(B12="","",IF(B12="Encaissement",E12,-E12))
H13: =IF(B13="","",IF(B13="Encaissement",E13,-E13))
H14: =IF(B14="","",IF(B14="Encaissement",E14,-E14))
H15: =IF(B15="","",IF(B15="Encaissement",E15,-E15))
H16: =IF(B16="","",IF(B16="Encaissement",E16,-E16))
H17: =IF(B17="","",IF(B17="Encaissement",E17,-E17))
H18: =IF(B18="","",IF(B18="Encaissement",E18,-E18))
... H502: =IF(B502="","",IF(B502="Encaissement",E502,-E502))

Sheet 04_TABLEAU_DE_BORD
A1: TABLEAU DE BORD DE TRÉSORERIE
A4: TRÉSORERIE ACTUELLE | B4: ='02_PARAMETRES'!B7+SUMIFS('03_FLUX'!$H$3:$H$502,'03_FLUX'!$F$3:$F$502,"Réalisé") | D4: PRÉVISION À 30 JOURS | E4: ='05_PREVISION'!F31
A8: PRÉVISION À 60 JOURS | B8: ='05_PREVISION'!F61 | D8: PRÉVISION À 90 JOURS | E8: ='05_PREVISION'!F91
A12: SEUIL DE SÉCURITÉ | B12: ='02_PARAMETRES'!B8 | D12: ÉCART AU SEUIL À 90 J. | E12: =E8-B12
A16: POINT DE TENSION PRÉVISIONNEL | B16: =IFERROR(INDEX('05_PREVISION'!A2:A91,MATCH(TRUE,'05_PREVISION'!F2:F91<'05_PREVISION'!G2:G91,0)),"Aucun sur 90 jours") | D16: DÉCAISSEMENTS À 7 JOURS | E16: =SUM('05_PREVISION'!C2:C8)
A20: =IF(MIN('05_PREVISION'!F2:F91)<'02_PARAMETRES'!B8,"⚠ ALERTE : votre trésorerie prévisionnelle passe sous votre seuil de sécurité. Consultez le point de tension et les flux à venir.",IF(MIN('05_PREVISION'!F2:F91)<'02_PARAMETRES'!B8*1.2,"⚠ VIGILANCE : votre trésorerie prévisionnelle se rapproche de votre seuil de sécurité.","✓ Situation normale : votre trésorerie prévisionnelle reste supérieure à votre seuil de sécurité."))
A25: ="Situation de trésorerie : solde actuel "&TEXT(B4,"#,##0.00 €")&". Sur les 90 prochains jours, le minimum prévisionnel est "&TEXT(MIN('05_PREVISION'!F2:F91),"#,##0.00 €")&"."

Sheet 05_PREVISION
A1: Date | B1: Encaissements prévus | C1: Décaissements prévus | D1: Encaissements réalisés | E1: Décaissements réalisés | F1: Solde prévisionnel | G1: Seuil de sécurité | H1: Alerte
A2: ='02_PARAMETRES'!B9 | B2: =SUMIFS('03_FLUX'!$E$3:$E$502,'03_FLUX'!$A$3:$A$502,A2,'03_FLUX'!$B$3:$B$502,"Encaissement",'03_FLUX'!$F$3:$F$502,"Prévu") | C2: =SUMIFS('03_FLUX'!$E$3:$E$502,'03_FLUX'!$A$3:$A$502,A2,'03_FLUX'!$B$3:$B$502,"Décaissement",'03_FLUX'!$F$3:$F$502,"Prévu") | D2: =SUMIFS('03_FLUX'!$E$3:$E$502,'03_FLUX'!$A$3:$A$502,A2,'03_FLUX'!$B$3:$B$502,"Encaissement",'03_FLUX'!$F$3:$F$502,"Réalisé") | E2: =SUMIFS('03_FLUX'!$E$3:$E$502,'03_FLUX'!$A$3:$A$502,A2,'03_FLUX'!$B$3:$B$502,"Décaissement",'03_FLUX'!$F$3:$F$502,"Réalisé") | F2: ='02_PARAMETRES'!B7+D2-E2+B2-C2 | G2: ='02_PARAMETRES'!B8 | H2: =IF(F2<G2,"ALERTE",IF(F2<G2*1.2,"VIGILANCE","NORMAL"))
A3: =A2+1 | B3: =SUMIFS('03_FLUX'!$E$3:$E$502,'03_FLUX'!$A$3:$A$502,A3,'03_FLUX'!$B$3:$B$502,"Encaissement",'03_FLUX'!$F$3:$F$502,"Prévu") | C3: =SUMIFS('03_FLUX'!$E$3:$E$502,'03_FLUX'!$A$3:$A$502,A3,'03_FLUX'!$B$3:$B$502,"Décaissement",'03_FLUX'!$F$3:$F$502,"Prévu") | D3: =SUMIFS('03_FLUX'!$E$3:$E$502,'03_FLUX'!$A$3:$A$502,A3,'03_FLUX'!$B$3:$B$502,"Encaissement",'03_FLUX'!$F$3:$F$502,"Réalisé") | E3: =SUMIFS('03_FLUX'!$E$3:$E$502,'03_FLUX'!$A$3:$A$502,A3,'03_FLUX'!$B$3:$B$502,"Décaissement",'03_FLUX'!$F$3:$F$502,"Réalisé") | F3: =F2+D3-E3+B3-C3 | G3: ='02_PARAMETRES'!B8 | H3: =IF(F3<G3,"ALERTE",IF(F3<G3*1.2,"VIGILANCE","NORMAL"))
A4: =A3+1 | B4: =SUMIFS('03_FLUX'!$E$3:$E$502,'03_FLUX'!$A$3:$A$502,A4,'03_FLUX'!$B$3:$B$502,"Encaissement",'03_FLUX'!$F$3:$F$502,"Prévu") | C4: =SUMIFS('03_FLUX'!$E$3:$E$502,'03_FLUX'!$A$3:$A$502,A4,'03_FLUX'!$B$3:$B$502,"Décaissement",'03_FLUX'!$F$3:$F$502,"Prévu") | D4: =SUMIFS('03_FLUX'!$E$3:$E$502,'03_FLUX'!$A$3:$A$502,A4,'03_FLUX'!$B$3:$B$502,"Encaissement",'03_FLUX'!$F$3:$F$502,"Réalisé") | E4: =SUMIFS('03_FLUX'!$E$3:$E$502,'03_FLUX'!$A$3:$A$502,A4,'03_FLUX'!$B$3:$B$502,"Décaissement",'03_FLUX'!$F$3:$F$502,"Réalisé") | F4: =F3+D4-E4+B4-C4 | G4: ='02_PARAMETRES'!B8 | H4: =IF(F4<G4,"ALERTE",IF(F4<G4*1.2,"VIGILANCE","NORMAL"))
A5: =A4+1 | B5: =SUMIFS('03_FLUX'!$E$3:$E$502,'03_FLUX'!$A$3:$A$502,A5,'03_FLUX'!$B$3:$B$502,"Encaissement",'03_FLUX'!$F$3:$F$502,"Prévu") | C5: =SUMIFS('03_FLUX'!$E$3:$E$502,'03_FLUX'!$A$3:$A$502,A5,'03_FLUX'!$B$3:$B$502,"Décaissement",'03_FLUX'!$F$3:$F$502,"Prévu") | D5: =SUMIFS('03_FLUX'!$E$3:$E$502,'03_FLUX'!$A$3:$A$502,A5,'03_FLUX'!$B$3:$B$502,"Encaissement",'03_FLUX'!$F$3:$F$502,"Réalisé") | E5: =SUMIFS('03_FLUX'!$E$3:$E$502,'03_FLUX'!$A$3:$A$502,A5,'03_FLUX'!$B$3:$B$502,"Décaissement",'03_FLUX'!$F$3:$F$502,"Réalisé") | F5: =F4+D5-E5+B5-C5 | G5: ='02_PARAMETRES'!B8 | H5: =IF(F5<G5,"ALERTE",IF(F5<G5*1.2,"VIGILANCE","NORMAL"))
A6: =A5+1 | B6: =SUMIFS('03_FLUX'!$E$3:$E$502,'03_FLUX'!$A$3:$A$502,A6,'03_FLUX'!$B$3:$B$502,"Encaissement",'03_FLUX'!$F$3:$F$502,"Prévu") | C6: =SUMIFS('03_FLUX'!$E$3:$E$502,'03_FLUX'!$A$3:$A$502,A6,'03_FLUX'!$B$3:$B$502,"Décaissement",'03_FLUX'!$F$3:$F$502,"Prévu") | D6: =SUMIFS('03_FLUX'!$E$3:$E$502,'03_FLUX'!$A$3:$A$502,A6,'03_FLUX'!$B$3:$B$502,"Encaissement",'03_FLUX'!$F$3:$F$502,"Réalisé") | E6: =SUMIFS('03_FLUX'!$E$3:$E$502,'03_FLUX'!$A$3:$A$502,A6,'03_FLUX'!$B$3:$B$502,"Décaissement",'03_FLUX'!$F$3:$F$502,"Réalisé") | F6: =F5+D6-E6+B6-C6 | G6: ='02_PARAMETRES'!B8 | H6: =IF(F6<G6,"ALERTE",IF(F6<G6*1.2,"VIGILANCE","NORMAL"))
A7: =A6+1 | B7: =SUMIFS('03_FLUX'!$E$3:$E$502,'03_FLUX'!$A$3:$A$502,A7,'03_FLUX'!$B$3:$B$502,"Encaissement",'03_FLUX'!$F$3:$F$502,"Prévu") | C7: =SUMIFS('03_FLUX'!$E$3:$E$502,'03_FLUX'!$A$3:$A$502,A7,'03_FLUX'!$B$3:$B$502,"Décaissement",'03_FLUX'!$F$3:$F$502,"Prévu") | D7: =SUMIFS('03_FLUX'!$E$3:$E$502,'03_FLUX'!$A$3:$A$502,A7,'03_FLUX'!$B$3:$B$502,"Encaissement",'03_FLUX'!$F$3:$F$502,"Réalisé") | E7: =SUMIFS('03_FLUX'!$E$3:$E$502,'03_FLUX'!$A$3:$A$502,A7,'03_FLUX'!$B$3:$B$502,"Décaissement",'03_FLUX'!$F$3:$F$502,"Réalisé") | F7: =F6+D7-E7+B7-C7 | G7: ='02_PARAMETRES'!B8 | H7: =IF(F7<G7,"ALERTE",IF(F7<G7*1.2,"VIGILANCE","NORMAL"))
A8: =A7+1 | B8: =SUMIFS('03_FLUX'!$E$3:$E$502,'03_FLUX'!$A$3:$A$502,A8,'03_FLUX'!$B$3:$B$502,"Encaissement",'03_FLUX'!$F$3:$F$502,"Prévu") | C8: =SUMIFS('03_FLUX'!$E$3:$E$502,'03_FLUX'!$A$3:$A$502,A8,'03_FLUX'!$B$3:$B$502,"Décaissement",'03_FLUX'!$F$3:$F$502,"Prévu") | D8: =SUMIFS('03_FLUX'!$E$3:$E$502,'03_FLUX'!$A$3:$A$502,A8,'03_FLUX'!$B$3:$B$502,"Encaissement",'03_FLUX'!$F$3:$F$502,"Réalisé") | E8: =SUMIFS('03_FLUX'!$E$3:$E$502,'03_FLUX'!$A$3:$A$502,A8,'03_FLUX'!$B$3:$B$502,"Décaissement",'03_FLUX'!$F$3:$F$502,"Réalisé") | F8: =F7+D8-E8+B8-C8 | G8: ='02_PARAMETRES'!B8 | H8: =IF(F8<G8,"ALERTE",IF(F8<G8*1.2,"VIGILANCE","NORMAL"))
A9: =A8+1 | B9: =SUMIFS('03_FLUX'!$E$3:$E$502,'03_FLUX'!$A$3:$A$502,A9,'03_FLUX'!$B$3:$B$502,"Encaissement",'03_FLUX'!$F$3:$F$502,"Prévu") | C9: =SUMIFS('03_FLUX'!$E$3:$E$502,'03_FLUX'!$A$3:$A$502,A9,'03_FLUX'!$B$3:$B$502,"Décaissement",'03_FLUX'!$F$3:$F$502,"Prévu") | D9: =SUMIFS('03_FLUX'!$E$3:$E$502,'03_FLUX'!$A$3:$A$502,A9,'03_FLUX'!$B$3:$B$502,"Encaissement",'03_FLUX'!$F$3:$F$502,"Réalisé") | E9: =SUMIFS('03_FLUX'!$E$3:$E$502,'03_FLUX'!$A$3:$A$502,A9,'03_FLUX'!$B$3:$B$502,"Décaissement",'03_FLUX'!$F$3:$F$502,"Réalisé") | F9: =F8+D9-E9+B9-C9 | G9: ='02_PARAMETRES'!B8 | H9: =IF(F9<G9,"ALERTE",IF(F9<G9*1.2,"VIGILANCE","NORMAL"))
A10: =A9+1 | B10: =SUMIFS('03_FLUX'!$E$3:$E$502,'03_FLUX'!$A$3:$A$502,A10,'03_FLUX'!$B$3:$B$502,"Encaissement",'03_FLUX'!$F$3:$F$502,"Prévu") | C10: =SUMIFS('03_FLUX'!$E$3:$E$502,'03_FLUX'!$A$3:$A$502,A10,'03_FLUX'!$B$3:$B$502,"Décaissement",'03_FLUX'!$F$3:$F$502,"Prévu") | D10: =SUMIFS('03_FLUX'!$E$3:$E$502,'03_FLUX'!$A$3:$A$502,A10,'03_FLUX'!$B$3:$B$502,"Encaissement",'03_FLUX'!$F$3:$F$502,"Réalisé") | E10: =SUMIFS('03_FLUX'!$E$3:$E$502,'03_FLUX'!$A$3:$A$502,A10,'03_FLUX'!$B$3:$B$502,"Décaissement",'03_FLUX'!$F$3:$F$502,"Réalisé") | F10: =F9+D10-E10+B10-C10 | G10: ='02_PARAMETRES'!B8 | H10: =IF(F10<G10,"ALERTE",IF(F10<G10*1.2,"VIGILANCE","NORMAL"))
A11: =A10+1 | B11: =SUMIFS('03_FLUX'!$E$3:$E$502,'03_FLUX'!$A$3:$A$502,A11,'03_FLUX'!$B$3:$B$502,"Encaissement",'03_FLUX'!$F$3:$F$502,"Prévu") | C11: =SUMIFS('03_FLUX'!$E$3:$E$502,'03_FLUX'!$A$3:$A$502,A11,'03_FLUX'!$B$3:$B$502,"Décaissement",'03_FLUX'!$F$3:$F$502,"Prévu") | D11: =SUMIFS('03_FLUX'!$E$3:$E$502,'03_FLUX'!$A$3:$A$502,A11,'03_FLUX'!$B$3:$B$502,"Encaissement",'03_FLUX'!$F$3:$F$502,"Réalisé") | E11: =SUMIFS('03_FLUX'!$E$3:$E$502,'03_FLUX'!$A$3:$A$502,A11,'03_FLUX'!$B$3:$B$502,"Décaissement",'03_FLUX'!$F$3:$F$502,"Réalisé") | F11: =F10+D11-E11+B11-C11 | G11: ='02_PARAMETRES'!B8 | H11: =IF(F11<G11,"ALERTE",IF(F11<G11*1.2,"VIGILANCE","NORMAL"))
A12: =A11+1 | B12: =SUMIFS('03_FLUX'!$E$3:$E$502,'03_FLUX'!$A$3:$A$502,A12,'03_FLUX'!$B$3:$B$502,"Encaissement",'03_FLUX'!$F$3:$F$502,"Prévu") | C12: =SUMIFS('03_FLUX'!$E$3:$E$502,'03_FLUX'!$A$3:$A$502,A12,'03_FLUX'!$B$3:$B$502,"Décaissement",'03_FLUX'!$F$3:$F$502,"Prévu") | D12: =SUMIFS('03_FLUX'!$E$3:$E$502,'03_FLUX'!$A$3:$A$502,A12,'03_FLUX'!$B$3:$B$502,"Encaissement",'03_FLUX'!$F$3:$F$502,"Réalisé") | E12: =SUMIFS('03_FLUX'!$E$3:$E$502,'03_FLUX'!$A$3:$A$502,A12,'03_FLUX'!$B$3:$B$502,"Décaissement",'03_FLUX'!$F$3:$F$502,"Réalisé") | F12: =F11+D12-E12+B12-C12 | G12: ='02_PARAMETRES'!B8 | H12: =IF(F12<G12,"ALERTE",IF(F12<G12*1.2,"VIGILANCE","NORMAL"))
A13: =A12+1 | B13: =SUMIFS('03_FLUX'!$E$3:$E$502,'03_FLUX'!$A$3:$A$502,A13,'03_FLUX'!$B$3:$B$502,"Encaissement",'03_FLUX'!$F$3:$F$502,"Prévu") | C13: =SUMIFS('03_FLUX'!$E$3:$E$502,'03_FLUX'!$A$3:$A$502,A13,'03_FLUX'!$B$3:$B$502,"Décaissement",'03_FLUX'!$F$3:$F$502,"Prévu") | D13: =SUMIFS('03_FLUX'!$E$3:$E$502,'03_FLUX'!$A$3:$A$502,A13,'03_FLUX'!$B$3:$B$502,"Encaissement",'03_FLUX'!$F$3:$F$502,"Réalisé") | E13: =SUMIFS('03_FLUX'!$E$3:$E$502,'03_FLUX'!$A$3:$A$502,A13,'03_FLUX'!$B$3:$B$502,"Décaissement",'03_FLUX'!$F$3:$F$502,"Réalisé") | F13: =F12+D13-E13+B13-C13 | G13: ='02_PARAMETRES'!B8 | H13: =IF(F13<G13,"ALERTE",IF(F13<G13*1.2,"VIGILANCE","NORMAL"))
A14: =A13+1 | B14: =SUMIFS('03_FLUX'!$E$3:$E$502,'03_FLUX'!$A$3:$A$502,A14,'03_FLUX'!$B$3:$B$502,"Encaissement",'03_FLUX'!$F$3:$F$502,"Prévu") | C14: =SUMIFS('03_FLUX'!$E$3:$E$502,'03_FLUX'!$A$3:$A$502,A14,'03_FLUX'!$B$3:$B$502,"Décaissement",'03_FLUX'!$F$3:$F$502,"Prévu") | D14: =SUMIFS('03_FLUX'!$E$3:$E$502,'03_FLUX'!$A$3:$A$502,A14,'03_FLUX'!$B$3:$B$502,"Encaissement",'03_FLUX'!$F$3:$F$502,"Réalisé") | E14: =SUMIFS('03_FLUX'!$E$3:$E$502,'03_FLUX'!$A$3:$A$502,A14,'03_FLUX'!$B$3:$B$502,"Décaissement",'03_FLUX'!$F$3:$F$502,"Réalisé") | F14: =F13+D14-E14+B14-C14 | G14: ='02_PARAMETRES'!B8 | H14: =IF(F14<G14,"ALERTE",IF(F14<G14*1.2,"VIGILANCE","NORMAL"))
A15: =A14+1 | B15: =SUMIFS('03_FLUX'!$E$3:$E$502,'03_FLUX'!$A$3:$A$502,A15,'03_FLUX'!$B$3:$B$502,"Encaissement",'03_FLUX'!$F$3:$F$502,"Prévu") | C15: =SUMIFS('03_FLUX'!$E$3:$E$502,'03_FLUX'!$A$3:$A$502,A15,'03_FLUX'!$B$3:$B$502,"Décaissement",'03_FLUX'!$F$3:$F$502,"Prévu") | D15: =SUMIFS('03_FLUX'!$E$3:$E$502,'03_FLUX'!$A$3:$A$502,A15,'03_FLUX'!$B$3:$B$502,"Encaissement",'03_FLUX'!$F$3:$F$502,"Réalisé") | E15: =SUMIFS('03_FLUX'!$E$3:$E$502,'03_FLUX'!$A$3:$A$502,A15,'03_FLUX'!$B$3:$B$502,"Décaissement",'03_FLUX'!$F$3:$F$502,"Réalisé") | F15: =F14+D15-E15+B15-C15 | G15: ='02_PARAMETRES'!B8 | H15: =IF(F15<G15,"ALERTE",IF(F15<G15*1.2,"VIGILANCE","NORMAL"))
A16: =A15+1 | B16: =SUMIFS('03_FLUX'!$E$3:$E$502,'03_FLUX'!$A$3:$A$502,A16,'03_FLUX'!$B$3:$B$502,"Encaissement",'03_FLUX'!$F$3:$F$502,"Prévu") | C16: =SUMIFS('03_FLUX'!$E$3:$E$502,'03_FLUX'!$A$3:$A$502,A16,'03_FLUX'!$B$3:$B$502,"Décaissement",'03_FLUX'!$F$3:$F$502,"Prévu") | D16: =SUMIFS('03_FLUX'!$E$3:$E$502,'03_FLUX'!$A$3:$A$502,A16,'03_FLUX'!$B$3:$B$502,"Encaissement",'03_FLUX'!$F$3:$F$502,"Réalisé") | E16: =SUMIFS('03_FLUX'!$E$3:$E$502,'03_FLUX'!$A$3:$A$502,A16,'03_FLUX'!$B$3:$B$502,"Décaissement",'03_FLUX'!$F$3:$F$502,"Réalisé") | F16: =F15+D16-E16+B16-C16 | G16: ='02_PARAMETRES'!B8 | H16: =IF(F16<G16,"ALERTE",IF(F16<G16*1.2,"VIGILANCE","NORMAL"))
A17: =A16+1 | B17: =SUMIFS('03_FLUX'!$E$3:$E$502,'03_FLUX'!$A$3:$A$502,A17,'03_FLUX'!$B$3:$B$502,"Encaissement",'03_FLUX'!$F$3:$F$502,"Prévu") | C17: =SUMIFS('03_FLUX'!$E$3:$E$502,'03_FLUX'!$A$3:$A$502,A17,'03_FLUX'!$B$3:$B$502,"Décaissement",'03_FLUX'!$F$3:$F$502,"Prévu") | D17: =SUMIFS('03_FLUX'!$E$3:$E$502,'03_FLUX'!$A$3:$A$502,A17,'03_FLUX'!$B$3:$B$502,"Encaissement",'03_FLUX'!$F$3:$F$502,"Réalisé") | E17: =SUMIFS('03_FLUX'!$E$3:$E$502,'03_FLUX'!$A$3:$A$502,A17,'03_FLUX'!$B$3:$B$502,"Décaissement",'03_FLUX'!$F$3:$F$502,"Réalisé") | F17: =F16+D17-E17+B17-C17 | G17: ='02_PARAMETRES'!B8 | H17: =IF(F17<G17,"ALERTE",IF(F17<G17*1.2,"VIGILANCE","NORMAL"))
A18: =A17+1 | B18: =SUMIFS('03_FLUX'!$E$3:$E$502,'03_FLUX'!$A$3:$A$502,A18,'03_FLUX'!$B$3:$B$502,"Encaissement",'03_FLUX'!$F$3:$F$502,"Prévu") | C18: =SUMIFS('03_FLUX'!$E$3:$E$502,'03_FLUX'!$A$3:$A$502,A18,'03_FLUX'!$B$3:$B$502,"Décaissement",'03_FLUX'!$F$3:$F$502,"Prévu") | D18: =SUMIFS('03_FLUX'!$E$3:$E$502,'03_FLUX'!$A$3:$A$502,A18,'03_FLUX'!$B$3:$B$502,"Encaissement",'03_FLUX'!$F$3:$F$502,"Réalisé") | E18: =SUMIFS('03_FLUX'!$E$3:$E$502,'03_FLUX'!$A$3:$A$502,A18,'03_FLUX'!$B$3:$B$502,"Décaissement",'03_FLUX'!$F$3:$F$502,"Réalisé") | F18: =F17+D18-E18+B18-C18 | G18: ='02_PARAMETRES'!B8 | H18: =IF(F18<G18,"ALERTE",IF(F18<G18*1.2,"VIGILANCE","NORMAL"))
A19: =A18+1 | B19: =SUMIFS('03_FLUX'!$E$3:$E$502,'03_FLUX'!$A$3:$A$502,A19,'03_FLUX'!$B$3:$B$502,"Encaissement",'03_FLUX'!$F$3:$F$502,"Prévu") | C19: =SUMIFS('03_FLUX'!$E$3:$E$502,'03_FLUX'!$A$3:$A$502,A19,'03_FLUX'!$B$3:$B$502,"Décaissement",'03_FLUX'!$F$3:$F$502,"Prévu") | D19: =SUMIFS('03_FLUX'!$E$3:$E$502,'03_FLUX'!$A$3:$A$502,A19,'03_FLUX'!$B$3:$B$502,"Encaissement",'03_FLUX'!$F$3:$F$502,"Réalisé") | E19: =SUMIFS('03_FLUX'!$E$3:$E$502,'03_FLUX'!$A$3:$A$502,A19,'03_FLUX'!$B$3:$B$502,"Décaissement",'03_FLUX'!$F$3:$F$502,"Réalisé") | F19: =F18+D19-E19+B19-C19 | G19: ='02_PARAMETRES'!B8 | H19: =IF(F19<G19,"ALERTE",IF(F19<G19*1.2,"VIGILANCE","NORMAL"))
A20: =A19+1 | B20: =SUMIFS('03_FLUX'!$E$3:$E$502,'03_FLUX'!$A$3:$A$502,A20,'03_FLUX'!$B$3:$B$502,"Encaissement",'03_FLUX'!$F$3:$F$502,"Prévu") | C20: =SUMIFS('03_FLUX'!$E$3:$E$502,'03_FLUX'!$A$3:$A$502,A20,'03_FLUX'!$B$3:$B$502,"Décaissement",'03_FLUX'!$F$3:$F$502,"Prévu") | D20: =SUMIFS('03_FLUX'!$E$3:$E$502,'03_FLUX'!$A$3:$A$502,A20,'03_FLUX'!$B$3:$B$502,"Encaissement",'03_FLUX'!$F$3:$F$502,"Réalisé") | E20: =SUMIFS('03_FLUX'!$E$3:$E$502,'03_FLUX'!$A$3:$A$502,A20,'03_FLUX'!$B$3:$B$502,"Décaissement",'03_FLUX'!$F$3:$F$502,"Réalisé") | F20: =F19+D20-E20+B20-C20 | G20: ='02_PARAMETRES'!B8 | H20: =IF(F20<G20,"ALERTE",IF(F20<G20*1.2,"VIGILANCE","NORMAL"))
A21: =A20+1 | B21: =SUMIFS('03_FLUX'!$E$3:$E$502,'03_FLUX'!$A$3:$A$502,A21,'03_FLUX'!$B$3:$B$502,"Encaissement",'03_FLUX'!$F$3:$F$502,"Prévu") | C21: =SUMIFS('03_FLUX'!$E$3:$E$502,'03_FLUX'!$A$3:$A$502,A21,'03_FLUX'!$B$3:$B$502,"Décaissement",'03_FLUX'!$F$3:$F$502,"Prévu") | D21: =SUMIFS('03_FLUX'!$E$3:$E$502,'03_FLUX'!$A$3:$A$502,A21,'03_FLUX'!$B$3:$B$502,"Encaissement",'03_FLUX'!$F$3:$F$502,"Réalisé") | E21: =SUMIFS('03_FLUX'!$E$3:$E$502,'03_FLUX'!$A$3:$A$502,A21,'03_FLUX'!$B$3:$B$502,"Décaissement",'03_FLUX'!$F$3:$F$502,"Réalisé") | F21: =F20+D21-E21+B21-C21 | G21: ='02_PARAMETRES'!B8 | H21: =IF(F21<G21,"ALERTE",IF(F21<G21*1.2,"VIGILANCE","NORMAL"))
A22: =A21+1 | B22: =SUMIFS('03_FLUX'!$E$3:$E$502,'03_FLUX'!$A$3:$A$502,A22,'03_FLUX'!$B$3:$B$502,"Encaissement",'03_FLUX'!$F$3:$F$502,"Prévu") | C22: =SUMIFS('03_FLUX'!$E$3:$E$502,'03_FLUX'!$A$3:$A$502,A22,'03_FLUX'!$B$3:$B$502,"Décaissement",'03_FLUX'!$F$3:$F$502,"Prévu") | D22: =SUMIFS('03_FLUX'!$E$3:$E$502,'03_FLUX'!$A$3:$A$502,A22,'03_FLUX'!$B$3:$B$502,"Encaissement",'03_FLUX'!$F$3:$F$502,"Réalisé") | E22: =SUMIFS('03_FLUX'!$E$3:$E$502,'03_FLUX'!$A$3:$A$502,A22,'03_FLUX'!$B$3:$B$502,"Décaissement",'03_FLUX'!$F$3:$F$502,"Réalisé") | F22: =F21+D22-E22+B22-C22 | G22: ='02_PARAMETRES'!B8 | H22: =IF(F22<G22,"ALERTE",IF(F22<G22*1.2,"VIGILANCE","NORMAL"))
A23: =A22+1 | B23: =SUMIFS('03_FLUX'!$E$3:$E$502,'03_FLUX'!$A$3:$A$502,A23,'03_FLUX'!$B$3:$B$502,"Encaissement",'03_FLUX'!$F$3:$F$502,"Prévu") | C23: =SUMIFS('03_FLUX'!$E$3:$E$502,'03_FLUX'!$A$3:$A$502,A23,'03_FLUX'!$B$3:$B$502,"Décaissement",'03_FLUX'!$F$3:$F$502,"Prévu") | D23: =SUMIFS('03_FLUX'!$E$3:$E$502,'03_FLUX'!$A$3:$A$502,A23,'03_FLUX'!$B$3:$B$502,"Encaissement",'03_FLUX'!$F$3:$F$502,"Réalisé") | E23: =SUMIFS('03_FLUX'!$E$3:$E$502,'03_FLUX'!$A$3:$A$502,A23,'03_FLUX'!$B$3:$B$502,"Décaissement",'03_FLUX'!$F$3:$F$502,"Réalisé") | F23: =F22+D23-E23+B23-C23 | G23: ='02_PARAMETRES'!B8 | H23: =IF(F23<G23,"ALERTE",IF(F23<G23*1.2,"VIGILANCE","NORMAL"))
A24: =A23+1 | B24: =SUMIFS('03_FLUX'!$E$3:$E$502,'03_FLUX'!$A$3:$A$502,A24,'03_FLUX'!$B$3:$B$502,"Encaissement",'03_FLUX'!$F$3:$F$502,"Prévu") | C24: =SUMIFS('03_FLUX'!$E$3:$E$502,'03_FLUX'!$A$3:$A$502,A24,'03_FLUX'!$B$3:$B$502,"Décaissement",'03_FLUX'!$F$3:$F$502,"Prévu") | D24: =SUMIFS('03_FLUX'!$E$3:$E$502,'03_FLUX'!$A$3:$A$502,A24,'03_FLUX'!$B$3:$B$502,"Encaissement",'03_FLUX'!$F$3:$F$502,"Réalisé") | E24: =SUMIFS('03_FLUX'!$E$3:$E$502,'03_FLUX'!$A$3:$A$502,A24,'03_FLUX'!$B$3:$B$502,"Décaissement",'03_FLUX'!$F$3:$F$502,"Réalisé") | F24: =F23+D24-E24+B24-C24 | G24: ='02_PARAMETRES'!B8 | H24: =IF(F24<G24,"ALERTE",IF(F24<G24*1.2,"VIGILANCE","NORMAL"))
A25: =A24+1 | B25: =SUMIFS('03_FLUX'!$E$3:$E$502,'03_FLUX'!$A$3:$A$502,A25,'03_FLUX'!$B$3:$B$502,"Encaissement",'03_FLUX'!$F$3:$F$502,"Prévu") | C25: =SUMIFS('03_FLUX'!$E$3:$E$502,'03_FLUX'!$A$3:$A$502,A25,'03_FLUX'!$B$3:$B$502,"Décaissement",'03_FLUX'!$F$3:$F$502,"Prévu") | D25: =SUMIFS('03_FLUX'!$E$3:$E$502,'03_FLUX'!$A$3:$A$502,A25,'03_FLUX'!$B$3:$B$502,"Encaissement",'03_FLUX'!$F$3:$F$502,"Réalisé") | E25: =SUMIFS('03_FLUX'!$E$3:$E$502,'03_FLUX'!$A$3:$A$502,A25,'03_FLUX'!$B$3:$B$502,"Décaissement",'03_FLUX'!$F$3:$F$502,"Réalisé") | F25: =F24+D25-E25+B25-C25 | G25: ='02_PARAMETRES'!B8 | H25: =IF(F25<G25,"ALERTE",IF(F25<G25*1.2,"VIGILANCE","NORMAL"))
A26: =A25+1 | B26: =SUMIFS('03_FLUX'!$E$3:$E$502,'03_FLUX'!$A$3:$A$502,A26,'03_FLUX'!$B$3:$B$502,"Encaissement",'03_FLUX'!$F$3:$F$502,"Prévu") | C26: =SUMIFS('03_FLUX'!$E$3:$E$502,'03_FLUX'!$A$3:$A$502,A26,'03_FLUX'!$B$3:$B$502,"Décaissement",'03_FLUX'!$F$3:$F$502,"Prévu") | D26: =SUMIFS('03_FLUX'!$E$3:$E$502,'03_FLUX'!$A$3:$A$502,A26,'03_FLUX'!$B$3:$B$502,"Encaissement",'03_FLUX'!$F$3:$F$502,"Réalisé") | E26: =SUMIFS('03_FLUX'!$E$3:$E$502,'03_FLUX'!$A$3:$A$502,A26,'03_FLUX'!$B$3:$B$502,"Décaissement",'03_FLUX'!$F$3:$F$502,"Réalisé") | F26: =F25+D26-E26+B26-C26 | G26: ='02_PARAMETRES'!B8 | H26: =IF(F26<G26,"ALERTE",IF(F26<G26*1.2,"VIGILANCE","NORMAL"))
A27: =A26+1 | B27: =SUMIFS('03_FLUX'!$E$3:$E$502,'03_FLUX'!$A$3:$A$502,A27,'03_FLUX'!$B$3:$B$502,"Encaissement",'03_FLUX'!$F$3:$F$502,"Prévu") | C27: =SUMIFS('03_FLUX'!$E$3:$E$502,'03_FLUX'!$A$3:$A$502,A27,'03_FLUX'!$B$3:$B$502,"Décaissement",'03_FLUX'!$F$3:$F$502,"Prévu") | D27: =SUMIFS('03_FLUX'!$E$3:$E$502,'03_FLUX'!$A$3:$A$502,A27,'03_FLUX'!$B$3:$B$502,"Encaissement",'03_FLUX'!$F$3:$F$502,"Réalisé") | E27: =SUMIFS('03_FLUX'!$E$3:$E$502,'03_FLUX'!$A$3:$A$502,A27,'03_FLUX'!$B$3:$B$502,"Décaissement",'03_FLUX'!$F$3:$F$502,"Réalisé") | F27: =F26+D27-E27+B27-C27 | G27: ='02_PARAMETRES'!B8 | H27: =IF(F27<G27,"ALERTE",IF(F27<G27*1.2,"VIGILANCE","NORMAL"))
A28: =A27+1 | B28: =SUMIFS('03_FLUX'!$E$3:$E$502,'03_FLUX'!$A$3:$A$502,A28,'03_FLUX'!$B$3:$B$502,"Encaissement",'03_FLUX'!$F$3:$F$502,"Prévu") | C28: =SUMIFS('03_FLUX'!$E$3:$E$502,'03_FLUX'!$A$3:$A$502,A28,'03_FLUX'!$B$3:$B$502,"Décaissement",'03_FLUX'!$F$3:$F$502,"Prévu") | D28: =SUMIFS('03_FLUX'!$E$3:$E$502,'03_FLUX'!$A$3:$A$502,A28,'03_FLUX'!$B$3:$B$502,"Encaissement",'03_FLUX'!$F$3:$F$502,"Réalisé") | E28: =SUMIFS('03_FLUX'!$E$3:$E$502,'03_FLUX'!$A$3:$A$502,A28,'03_FLUX'!$B$3:$B$502,"Décaissement",'03_FLUX'!$F$3:$F$502,"Réalisé") | F28: =F27+D28-E28+B28-C28 | G28: ='02_PARAMETRES'!B8 | H28: =IF(F28<G28,"ALERTE",IF(F28<G28*1.2,"VIGILANCE","NORMAL"))
A29: =A28+1 | B29: =SUMIFS('03_FLUX'!$E$3:$E$502,'03_FLUX'!$A$3:$A$502,A29,'03_FLUX'!$B$3:$B$502,"Encaissement",'03_FLUX'!$F$3:$F$502,"Prévu") | C29: =SUMIFS('03_FLUX'!$E$3:$E$502,'03_FLUX'!$A$3:$A$502,A29,'03_FLUX'!$B$3:$B$502,"Décaissement",'03_FLUX'!$F$3:$F$502,"Prévu") | D29: =SUMIFS('03_FLUX'!$E$3:$E$502,'03_FLUX'!$A$3:$A$502,A29,'03_FLUX'!$B$3:$B$502,"Encaissement",'03_FLUX'!$F$3:$F$502,"Réalisé") | E29: =SUMIFS('03_FLUX'!$E$3:$E$502,'03_FLUX'!$A$3:$A$502,A29,'03_FLUX'!$B$3:$B$502,"Décaissement",'03_FLUX'!$F$3:$F$502,"Réalisé") | F29: =F28+D29-E29+B29-C29 | G29: ='02_PARAMETRES'!B8 | H29: =IF(F29<G29,"ALERTE",IF(F29<G29*1.2,"VIGILANCE","NORMAL"))
A30: =A29+1 | B30: =SUMIFS('03_FLUX'!$E$3:$E$502,'03_FLUX'!$A$3:$A$502,A30,'03_FLUX'!$B$3:$B$502,"Encaissement",'03_FLUX'!$F$3:$F$502,"Prévu") | C30: =SUMIFS('03_FLUX'!$E$3:$E$502,'03_FLUX'!$A$3:$A$502,A30,'03_FLUX'!$B$3:$B$502,"Décaissement",'03_FLUX'!$F$3:$F$502,"Prévu") | D30: =SUMIFS('03_FLUX'!$E$3:$E$502,'03_FLUX'!$A$3:$A$502,A30,'03_FLUX'!$B$3:$B$502,"Encaissement",'03_FLUX'!$F$3:$F$502,"Réalisé") | E30: =SUMIFS('03_FLUX'!$E$3:$E$502,'03_FLUX'!$A$3:$A$502,A30,'03_FLUX'!$B$3:$B$502,"Décaissement",'03_FLUX'!$F$3:$F$502,"Réalisé") | F30: =F29+D30-E30+B30-C30 | G30: ='02_PARAMETRES'!B8 | H30: =IF(F30<G30,"ALERTE",IF(F30<G30*1.2,"VIGILANCE","NORMAL"))
A31: =A30+1 | B31: =SUMIFS('03_FLUX'!$E$3:$E$502,'03_FLUX'!$A$3:$A$502,A31,'03_FLUX'!$B$3:$B$502,"Encaissement",'03_FLUX'!$F$3:$F$502,"Prévu") | C31: =SUMIFS('03_FLUX'!$E$3:$E$502,'03_FLUX'!$A$3:$A$502,A31,'03_FLUX'!$B$3:$B$502,"Décaissement",'03_FLUX'!$F$3:$F$502,"Prévu") | D31: =SUMIFS('03_FLUX'!$E$3:$E$502,'03_FLUX'!$A$3:$A$502,A31,'03_FLUX'!$B$3:$B$502,"Encaissement",'03_FLUX'!$F$3:$F$502,"Réalisé") | E31: =SUMIFS('03_FLUX'!$E$3:$E$502,'03_FLUX'!$A$3:$A$502,A31,'03_FLUX'!$B$3:$B$502,"Décaissement",'03_FLUX'!$F$3:$F$502,"Réalisé") | F31: =F30+D31-E31+B31-C31 | G31: ='02_PARAMETRES'!B8 | H31: =IF(F31<G31,"ALERTE",IF(F31<G31*1.2,"VIGILANCE","NORMAL"))
A32: =A31+1 | B32: =SUMIFS('03_FLUX'!$E$3:$E$502,'03_FLUX'!$A$3:$A$502,A32,'03_FLUX'!$B$3:$B$502,"Encaissement",'03_FLUX'!$F$3:$F$502,"Prévu") | C32: =SUMIFS('03_FLUX'!$E$3:$E$502,'03_FLUX'!$A$3:$A$502,A32,'03_FLUX'!$B$3:$B$502,"Décaissement",'03_FLUX'!$F$3:$F$502,"Prévu") | D32: =SUMIFS('03_FLUX'!$E$3:$E$502,'03_FLUX'!$A$3:$A$502,A32,'03_FLUX'!$B$3:$B$502,"Encaissement",'03_FLUX'!$F$3:$F$502,"Réalisé") | E32: =SUMIFS('03_FLUX'!$E$3:$E$502,'03_FLUX'!$A$3:$A$502,A32,'03_FLUX'!$B$3:$B$502,"Décaissement",'03_FLUX'!$F$3:$F$502,"Réalisé") | F32: =F31+D32-E32+B32-C32 | G32: ='02_PARAMETRES'!B8 | H32: =IF(F32<G32,"ALERTE",IF(F32<G32*1.2,"VIGILANCE","NORMAL"))
A33: =A32+1 | B33: =SUMIFS('03_FLUX'!$E$3:$E$502,'03_FLUX'!$A$3:$A$502,A33,'03_FLUX'!$B$3:$B$502,"Encaissement",'03_FLUX'!$F$3:$F$502,"Prévu") | C33: =SUMIFS('03_FLUX'!$E$3:$E$502,'03_FLUX'!$A$3:$A$502,A33,'03_FLUX'!$B$3:$B$502,"Décaissement",'03_FLUX'!$F$3:$F$502,"Prévu") | D33: =SUMIFS('03_FLUX'!$E$3:$E$502,'03_FLUX'!$A$3:$A$502,A33,'03_FLUX'!$B$3:$B$502,"Encaissement",'03_FLUX'!$F$3:$F$502,"Réalisé") | E33: =SUMIFS('03_FLUX'!$E$3:$E$502,'03_FLUX'!$A$3:$A$502,A33,'03_FLUX'!$B$3:$B$502,"Décaissement",'03_FLUX'!$F$3:$F$502,"Réalisé") | F33: =F32+D33-E33+B33-C33 | G33: ='02_PARAMETRES'!B8 | H33: =IF(F33<G33,"ALERTE",IF(F33<G33*1.2,"VIGILANCE","NORMAL"))
A34: =A33+1 | B34: =SUMIFS('03_FLUX'!$E$3:$E$502,'03_FLUX'!$A$3:$A$502,A34,'03_FLUX'!$B$3:$B$502,"Encaissement",'03_FLUX'!$F$3:$F$502,"Prévu") | C34: =SUMIFS('03_FLUX'!$E$3:$E$502,'03_FLUX'!$A$3:$A$502,A34,'03_FLUX'!$B$3:$B$502,"Décaissement",'03_FLUX'!$F$3:$F$502,"Prévu") | D34: =SUMIFS('03_FLUX'!$E$3:$E$502,'03_FLUX'!$A$3:$A$502,A34,'03_FLUX'!$B$3:$B$502,"Encaissement",'03_FLUX'!$F$3:$F$502,"Réalisé") | E34: =SUMIFS('03_FLUX'!$E$3:$E$502,'03_FLUX'!$A$3:$A$502,A34,'03_FLUX'!$B$3:$B$502,"Décaissement",'03_FLUX'!$F$3:$F$502,"Réalisé") | F34: =F33+D34-E34+B34-C34 | G34: ='02_PARAMETRES'!B8 | H34: =IF(F34<G34,"ALERTE",IF(F34<G34*1.2,"VIGILANCE","NORMAL"))
A35: =A34+1 | B35: =SUMIFS('03_FLUX'!$E$3:$E$502,'03_FLUX'!$A$3:$A$502,A35,'03_FLUX'!$B$3:$B$502,"Encaissement",'03_FLUX'!$F$3:$F$502,"Prévu") | C35: =SUMIFS('03_FLUX'!$E$3:$E$502,'03_FLUX'!$A$3:$A$502,A35,'03_FLUX'!$B$3:$B$502,"Décaissement",'03_FLUX'!$F$3:$F$502,"Prévu") | D35: =SUMIFS('03_FLUX'!$E$3:$E$502,'03_FLUX'!$A$3:$A$502,A35,'03_FLUX'!$B$3:$B$502,"Encaissement",'03_FLUX'!$F$3:$F$502,"Réalisé") | E35: =SUMIFS('03_FLUX'!$E$3:$E$502,'03_FLUX'!$A$3:$A$502,A35,'03_FLUX'!$B$3:$B$502,"Décaissement",'03_FLUX'!$F$3:$F$502,"Réalisé") | F35: =F34+D35-E35+B35-C35 | G35: ='02_PARAMETRES'!B8 | H35: =IF(F35<G35,"ALERTE",IF(F35<G35*1.2,"VIGILANCE","NORMAL"))
A36: =A35+1 | B36: =SUMIFS('03_FLUX'!$E$3:$E$502,'03_FLUX'!$A$3:$A$502,A36,'03_FLUX'!$B$3:$B$502,"Encaissement",'03_FLUX'!$F$3:$F$502,"Prévu") | C36: =SUMIFS('03_FLUX'!$E$3:$E$502,'03_FLUX'!$A$3:$A$502,A36,'03_FLUX'!$B$3:$B$502,"Décaissement",'03_FLUX'!$F$3:$F$502,"Prévu") | D36: =SUMIFS('03_FLUX'!$E$3:$E$502,'03_FLUX'!$A$3:$A$502,A36,'03_FLUX'!$B$3:$B$502,"Encaissement",'03_FLUX'!$F$3:$F$502,"Réalisé") | E36: =SUMIFS('03_FLUX'!$E$3:$E$502,'03_FLUX'!$A$3:$A$502,A36,'03_FLUX'!$B$3:$B$502,"Décaissement",'03_FLUX'!$F$3:$F$502,"Réalisé") | F36: =F35+D36-E36+B36-C36 | G36: ='02_PARAMETRES'!B8 | H36: =IF(F36<G36,"ALERTE",IF(F36<G36*1.2,"VIGILANCE","NORMAL"))
A37: =A36+1 | B37: =SUMIFS('03_FLUX'!$E$3:$E$502,'03_FLUX'!$A$3:$A$502,A37,'03_FLUX'!$B$3:$B$502,"Encaissement",'03_FLUX'!$F$3:$F$502,"Prévu") | C37: =SUMIFS('03_FLUX'!$E$3:$E$502,'03_FLUX'!$A$3:$A$502,A37,'03_FLUX'!$B$3:$B$502,"Décaissement",'03_FLUX'!$F$3:$F$502,"Prévu") | D37: =SUMIFS('03_FLUX'!$E$3:$E$502,'03_FLUX'!$A$3:$A$502,A37,'03_FLUX'!$B$3:$B$502,"Encaissement",'03_FLUX'!$F$3:$F$502,"Réalisé") | E37: =SUMIFS('03_FLUX'!$E$3:$E$502,'03_FLUX'!$A$3:$A$502,A37,'03_FLUX'!$B$3:$B$502,"Décaissement",'03_FLUX'!$F$3:$F$502,"Réalisé") | F37: =F36+D37-E37+B37-C37 | G37: ='02_PARAMETRES'!B8 | H37: =IF(F37<G37,"ALERTE",IF(F37<G37*1.2,"VIGILANCE","NORMAL"))
A38: =A37+1 | B38: =SUMIFS('03_FLUX'!$E$3:$E$502,'03_FLUX'!$A$3:$A$502,A38,'03_FLUX'!$B$3:$B$502,"Encaissement",'03_FLUX'!$F$3:$F$502,"Prévu") | C38: =SUMIFS('03_FLUX'!$E$3:$E$502,'03_FLUX'!$A$3:$A$502,A38,'03_FLUX'!$B$3:$B$502,"Décaissement",'03_FLUX'!$F$3:$F$502,"Prévu") | D38: =SUMIFS('03_FLUX'!$E$3:$E$502,'03_FLUX'!$A$3:$A$502,A38,'03_FLUX'!$B$3:$B$502,"Encaissement",'03_FLUX'!$F$3:$F$502,"Réalisé") | E38: =SUMIFS('03_FLUX'!$E$3:$E$502,'03_FLUX'!$A$3:$A$502,A38,'03_FLUX'!$B$3:$B$502,"Décaissement",'03_FLUX'!$F$3:$F$502,"Réalisé") | F38: =F37+D38-E38+B38-C38 | G38: ='02_PARAMETRES'!B8 | H38: =IF(F38<G38,"ALERTE",IF(F38<G38*1.2,"VIGILANCE","NORMAL"))
A39: =A38+1 | B39: =SUMIFS('03_FLUX'!$E$3:$E$502,'03_FLUX'!$A$3:$A$502,A39,'03_FLUX'!$B$3:$B$502,"Encaissement",'03_FLUX'!$F$3:$F$502,"Prévu") | C39: =SUMIFS('03_FLUX'!$E$3:$E$502,'03_FLUX'!$A$3:$A$502,A39,'03_FLUX'!$B$3:$B$502,"Décaissement",'03_FLUX'!$F$3:$F$502,"Prévu") | D39: =SUMIFS('03_FLUX'!$E$3:$E$502,'03_FLUX'!$A$3:$A$502,A39,'03_FLUX'!$B$3:$B$502,"Encaissement",'03_FLUX'!$F$3:$F$502,"Réalisé") | E39: =SUMIFS('03_FLUX'!$E$3:$E$502,'03_FLUX'!$A$3:$A$502,A39,'03_FLUX'!$B$3:$B$502,"Décaissement",'03_FLUX'!$F$3:$F$502,"Réalisé") | F39: =F38+D39-E39+B39-C39 | G39: ='02_PARAMETRES'!B8 | H39: =IF(F39<G39,"ALERTE",IF(F39<G39*1.2,"VIGILANCE","NORMAL"))
A40: =A39+1 | B40: =SUMIFS('03_FLUX'!$E$3:$E$502,'03_FLUX'!$A$3:$A$502,A40,'03_FLUX'!$B$3:$B$502,"Encaissement",'03_FLUX'!$F$3:$F$502,"Prévu") | C40: =SUMIFS('03_FLUX'!$E$3:$E$502,'03_FLUX'!$A$3:$A$502,A40,'03_FLUX'!$B$3:$B$502,"Décaissement",'03_FLUX'!$F$3:$F$502,"Prévu") | D40: =SUMIFS('03_FLUX'!$E$3:$E$502,'03_FLUX'!$A$3:$A$502,A40,'03_FLUX'!$B$3:$B$502,"Encaissement",'03_FLUX'!$F$3:$F$502,"Réalisé") | E40: =SUMIFS('03_FLUX'!$E$3:$E$502,'03_FLUX'!$A$3:$A$502,A40,'03_FLUX'!$B$3:$B$502,"Décaissement",'03_FLUX'!$F$3:$F$502,"Réalisé") | F40: =F39+D40-E40+B40-C40 | G40: ='02_PARAMETRES'!B8 | H40: =IF(F40<G40,"ALERTE",IF(F40<G40*1.2,"VIGILANCE","NORMAL"))
...

Sheet 06_AIDE
A1: AIDE — TABLEAU DE SUIVI DE TRÉSORERIE
A3: 1. Configurer | B3: Dans 02_PARAMETRES, renseignez le solde initial, sa date et votre seuil de sécurité.
A6: 2. Saisir | B6: Dans 03_FLUX, saisissez chaque flux avec un montant toujours positif. Le type Encaissement ou Décaissement gère le signe automatiquement.
A9: 3. Prévoir | B9: Les flux Prévu alimentent automatiquement la projection quotidienne de 90 jours.
A12: 4. Lire le tableau de bord | B12: Le tableau de bord affiche les soldes à 30, 60 et 90 jours, ainsi que la première date de passage sous le seuil.
A15: 5. Comprendre les alertes | B15: Normal : au-dessus du seuil. Vigilance : à moins de 20 % du seuil. Alerte : sous le seuil de sécurité.

Sheet 99_LISTES
A1: Types | B1: Catégories | C1: Statuts
A2: Encaissement | B2: Ventes | C2: Réalisé
A3: Décaissement | B3: Prestations | C3: Prévu
B4: Acomptes
B5: Autres encaissements
B6: Achats
B7: Fournisseurs
B8: Sous-traitance
B9: Salaires
B10: Charges sociales
B11: Impôts et taxes
B12: TVA
B13: Loyer
B14: Assurances
B15: Énergie
... B21: Autres dépenses
